{"uuid": "6dfbda24-d83b-45c7-8833-82e06536dd88", "children": ["5310bc92-36e3-4d01-9a66-f2aea152ac02"], "befores": [{"name": "app_driver", "status": "broken", "statusDetails": {"message": "selenium.common.exceptions.WebDriverException: Message: An unknown server-side error occurred while processing the command. Original error: The instrumentation process cannot be initialized within 30000ms timeout. Make sure the application under test does not crash and investigate the logcat output. You could also try to increase the value of 'uiautomator2ServerLaunchTimeout' capability. \nStacktrace:\nUnknownError: An unknown server-side error occurred while processing the command. Original error: The instrumentation process cannot be initialized within 30000ms timeout. Make sure the application under test does not crash and investigate the logcat output. You could also try to increase the value of 'uiautomator2ServerLaunchTimeout' capability. \n    at getResponseForW3CError (C:\\Program Files\\Appium\\resources\\app\\node_modules\\appium\\node_modules\\appium-base-driver\\lib\\protocol\\errors.js:804:9)\n    at asyncHandler (C:\\Program Files\\Appium\\resources\\app\\node_modules\\appium\\node_modules\\appium-base-driver\\lib\\protocol\\protocol.js:388:37)\n    at process._tickCallback (internal/process/next_tick.js:68:7)\n", "trace": "  File \"D:\\python\\Lib\\site-packages\\pluggy\\_callers.py\", line 38, in run_old_style_hookwrapper\n    res = yield\n          ^^^^^\n  File \"D:\\python\\Lib\\site-packages\\pluggy\\_callers.py\", line 139, in _multicall\n    teardown.throw(exception)\n  File \"D:\\python\\Lib\\site-packages\\_pytest\\setuponly.py\", line 36, in pytest_fixture_setup\n    return (yield)\n            ^^^^^\n  File \"D:\\python\\Lib\\site-packages\\pluggy\\_callers.py\", line 121, in _multicall\n    res = hook_impl.function(*args)\n          ^^^^^^^^^^^^^^^^^^^^^^^^^\n  File \"D:\\python\\Lib\\site-packages\\_pytest\\fixtures.py\", line 1195, in pytest_fixture_setup\n    result = call_fixture_func(fixturefunc, request, kwargs)\n             ^^^^^^^^^^^^^^^^^^^^^^^^^^^^^^^^^^^^^^^^^^^^^^^\n  File \"D:\\python\\Lib\\site-packages\\_pytest\\fixtures.py\", line 922, in call_fixture_func\n    fixture_result = next(generator)\n                     ^^^^^^^^^^^^^^^\n  File \"D:\\clear6Trubo\\conftest.py\", line 413, in app_driver\n    driver = init_driver()\n             ^^^^^^^^^^^^^\n  File \"D:\\clear6Trubo\\utils\\driver.py\", line 22, in init_driver\n    driver = webdriver.Remote(\n             ^^^^^^^^^^^^^^^^^\n  File \"D:\\python\\Lib\\site-packages\\appium\\webdriver\\webdriver.py\", line 238, in __init__\n    super().__init__(\n  File \"D:\\python\\Lib\\site-packages\\selenium\\webdriver\\remote\\webdriver.py\", line 257, in __init__\n    self.start_session(capabilities)\n  File \"D:\\python\\Lib\\site-packages\\appium\\webdriver\\webdriver.py\", line 329, in start_session\n    response = self.execute(RemoteCommand.NEW_SESSION, w3c_caps)\n               ^^^^^^^^^^^^^^^^^^^^^^^^^^^^^^^^^^^^^^^^^^^^^^^^^\n  File \"D:\\python\\Lib\\site-packages\\selenium\\webdriver\\remote\\webdriver.py\", line 447, in execute\n    self.error_handler.check_response(response)\n  File \"D:\\python\\Lib\\site-packages\\selenium\\webdriver\\remote\\errorhandler.py\", line 232, in check_response\n    raise exception_class(message, screen, stacktrace)\n"}, "start": 1755153498547, "stop": 1755153568774}], "start": 1755153498547, "stop": 1755153568938}