2025-08-14 14:38:19 | INFO | conftest.py:391 | ✅ 成功删除数据库文件: /storage/emulated/0/hwsys/database/clouds.db
2025-08-14 14:38:19 | DEBUG | remote_connection.py:403 | POST http://127.0.0.1:4723/wd/hub/session {'capabilities': {'firstMatch': [{}], 'alwaysMatch': {'appium:automationName': 'UiAutomator2', 'platformName': 'Android', 'appium:platformVersion': '14', 'appium:deviceName': 'Clear6 Turbo', 'appium:appPackage': 'hanvon.aebr.hanvondrive', 'appium:appActivity': 'hanvon.aebr.hanvondrive.activity.MainActivity', 'appium:fastReset': True, 'appium:noReset': False, 'appium:autoGrantPermissions': True, 'appium:recordScreen': True, 'appium:newCommandTimeout': 300}}}
2025-08-14 14:38:19 | DEBUG | connectionpool.py:241 | Starting new HTTP connection (1): 127.0.0.1:4723
2025-08-14 14:39:28 | DEBUG | connectionpool.py:544 | http://127.0.0.1:4723 "POST /wd/hub/session HTTP/1.1" 500 0
2025-08-14 14:39:28 | DEBUG | remote_connection.py:436 | Remote response: status=500 | data={"value":{"error":"unknown error","message":"An unknown server-side error occurred while processing the command. Original error: The instrumentation process cannot be initialized within 30000ms timeout. Make sure the application under test does not crash and investigate the logcat output. You could also try to increase the value of 'uiautomator2ServerLaunchTimeout' capability. ","stacktrace":"UnknownError: An unknown server-side error occurred while processing the command. Original error: The instrumentation process cannot be initialized within 30000ms timeout. Make sure the application under test does not crash and investigate the logcat output. You could also try to increase the value of 'uiautomator2ServerLaunchTimeout' capability. \n    at getResponseForW3CError (C:\\Program Files\\Appium\\resources\\app\\node_modules\\appium\\node_modules\\appium-base-driver\\lib\\protocol\\errors.js:804:9)\n    at asyncHandler (C:\\Program Files\\Appium\\resources\\app\\node_modules\\appium\\node_modules\\appium-base-driver\\lib\\protocol\\protocol.js:388:37)\n    at process._tickCallback (internal/process/next_tick.js:68:7)"}} | headers=HTTPHeaderDict({'X-Powered-By': 'Express', 'Vary': 'X-HTTP-Method-Override', 'Content-Type': 'application/json; charset=utf-8', 'Content-Length': '1134', 'ETag': 'W/"46e-HdhqhBMZRtSdWxd4iSppyKLYbjY"', 'Date': 'Thu, 14 Aug 2025 06:39:28 GMT', 'Connection': 'keep-alive'})
2025-08-14 14:39:28 | DEBUG | remote_connection.py:465 | Finished Request